Workbook
Name GroupAName: Settings!$B$5
Name GroupBName: Settings!$B$6
Name GroupCName: Settings!$B$7
Name GroupNamesRange: Settings!$B$5:$B$7
Name GroupPlusAllTeam: Settings!$A$34:$A$37
Name GroupPlusAllLevels: Settings!$C$34:$C$37
Name BlockTypesList: Settings!$A$40:$A$47
Name SeasonStart: Settings!$B$16
Name NumWeeks: Settings!$B$17
Name RosterFullNames: 'Athlete Profiles'!$D$6:$D$37
Name RosterGroupCol: 'Athlete Profiles'!$F$6:$F$37
Name AllCoachNames: 'Coach Profiles'!$D$6:$D$19
Name MondayCoachList: 'Coach Profiles'!$T$6:$T$13
Name TuesdayCoachList: 'Coach Profiles'!$U$6:$U$13
Name ThursdayCoachList: 'Coach Profiles'!$V$6:$V$13
Name LogDayRank: 'Log a Workout'!$I$5:$I$200
Name ExerciseNames: 'Exercise Library'!$D$6:$D$120

Sheet Read Me
A1: Rock Team — Tiered Practice System (Proposal)
A2: A working draft for discussion with the head coach — every default below is editable and meant to be argued with. Built mobile-first, since that's how most coaches will actually open it.
A4: What this changes
A5: Right now everyone on a given day gets the same workout regardless of level, which stretches our top climbers too thin and rushes our newest climbers. This workbook splits the team into three skill tiers and gives each tier a properly planned, individualized 90-minute block on Thursdays on a rotating basis (see Rotation Schedule for exactly how the 4-week cycle works).
A9: The 3 tabs you'll actually use — all work fully on a phone
A10: Log a Workout | C10: Plan a session: tap in the date, group, and (fastest) a pick from the Exercise Library — Block Type/Description/Sets-Reps fill themselves in, still editable. It's on Day View the instant you type it; no button to press, nothing to save separately.
A12: Day View | C12: Pick a date, scroll down. The whole day's plan, laid out to read top-to-bottom on a phone — nobody needs to scroll sideways or squint at a tiny grid.
A14: Athlete Profiles | C14: The roster. Type straight into the grid any time — no app or menu required. On a computer, Team Tools also offers a pop-up form for this if you'd rather use that; it just isn't available on the phone app.
A17: A note on "Team Tools": the pop-up add/edit forms and menu (Extensions > Apps Script setup) only work in a real browser — desktop, or a phone's browser at sheets.google.com — never inside the Google Sheets phone app. That's a Google limitation, not something fixable in the script. Everything above works without it regardless: typing into a cell and picking from a dropdown both work perfectly in the phone app.
A20: Everything else (tucked away, still here when you need it)
A21: Coach Profiles | C21: Same idea as Athlete Profiles, for coaches — including which day(s) they coach, which drives the rotation below.
A23: Exercise Library | C23: The catalog Log a Workout pulls from. Add a new entry any time, right in the blank rows.
A25: Rotation Schedule | C25: The Thursday-by-Thursday detail: which tier is featured, who's the lead planning coach.
A27: Full Team Calendar | C27: Every Monday/Tuesday/Thursday for the whole season at a glance — the piece that lets this grow into a full-team tool later.
A29: Progress Log | C29: Grade progress, comp results, benchmarks, coach notes over time — one row per data point.
A31: Settings | C31: Rename a tier, add a block type, change the season start date — everything else in the workbook updates automatically.
A34: Optional: add real clickable buttons (desktop, ~5 min, one time)
A35: Every function below is already in the script and already on the Team Tools menu — this step just gives it a clickable button too. For each row: Insert > Drawing, draw a small rounded rectangle, add the label text, Save and Close, then click the drawing's ⋮ menu > Assign script, and type the function name exactly as shown.
A37: Button | C37: Function to assign | E37: What it does / where to put it
A38: 🏠 Home | C38: goHome | E38: Jump back to this Read Me tab. Good on every tab, top corner.
A39: 📅 Today's Workout | C39: openTodaysWorkout | E39: Jump to Day View, dated today. Good on Read Me, or anywhere.
A40: ➕ Start New Workout Entry | C40: startNewWorkoutEntry | E40: Jump to Log a Workout, next blank row dated today. Good on Read Me or Day View.
A41: 🗑 Clear This Day's Plan | C41: clearDayPlan | E41: Wipes Day View's current date, with a confirmation. Good on Day View.
A42: 👤 Add Athlete | C42: showAddAthleteForm | E42: Pops up the add-athlete form. Good on Athlete Profiles.
A43: 🧗 Add Coach | C43: showAddCoachForm | E43: Pops up the add-coach form. Good on Coach Profiles.
A44: 📚 Add Exercise | C44: showAddExerciseForm | E44: Pops up the add-exercise form. Good on Exercise Library.
A46: These buttons only render and respond to clicks in a browser (desktop, or a phone's browser at sheets.google.com) — Google doesn't run drawing scripts inside the Sheets phone app. On a phone, use the Team Tools menu for these, or the two checkboxes on Day View and Log a Workout, which work everywhere.
A49: Color legend:
B50: Advanced tier | C50: Intermediate tier | D50: Developing tier | E50: All-Team week | F50: Cell to edit

Sheet Log a Workout
A1: Log a Workout
A2: Works fully on a phone — no app menu needed. Fastest path on mobile: tap Date, tap Group, tap "Pick from Library," done — Block Type/Description/Sets-Reps fill themselves in. It shows up on Day View the moment you enter it, for any coach to see. Planning something new? Leave "Pick from Library" blank and just type the Description yourself.
A3: Start today's entry: | B3: FALSE | C3: Tap TRUE — a new row gets today's date, ready to fill in. Works from a phone.
A4: Date | B4: Group | C4: Pick from Library (optional) | D4: Block Type | E4: Description / Activity (auto-fills, editable) | F4: Sets x Reps / Duration (auto-fills, editable) | G4: Coach | H4: Notes | I4: Day Rk
A5: 46287 | B5: Advanced | D5: Warm-up | E5: Team warm up | F5: 5:30-6:15 PM | H5: EXAMPLE — reformatted from the 9/22 plan, overwrite or delete | I5: =IF($A5="","",IF($A5='Day View'!$B$4,COUNTIFS($A$5:$A5,'Day View'!$B$4),""))
A6: 46287 | B6: Advanced | D6: Power | E6: Dynos in groups. Doesn't need to be coordinated — slab or steep. | F6: 6:15-7:00 PM | H6: EXAMPLE | I6: =IF($A6="","",IF($A6='Day View'!$B$4,COUNTIFS($A$5:$A6,'Day View'!$B$4),""))
A7: 46287 | B7: Advanced | C7: Foot Cut Drill | D7: =IFERROR(INDEX('Exercise Library'!$B$6:$B$120,MATCH(C7,ExerciseNames,0)),"") | E7: =IFERROR(INDEX('Exercise Library'!$E$6:$E$120,MATCH(C7,ExerciseNames,0)),"") | F7: =IFERROR(INDEX('Exercise Library'!$F$6:$F$120,MATCH(C7,ExerciseNames,0)),"") | H7: EXAMPLE — picked from the Library, so Block Type/Description/Sets-Reps auto-filled | I7: =IF($A7="","",IF($A7='Day View'!$B$4,COUNTIFS($A$5:$A7,'Day View'!$B$4),""))
A8: 46287 | B8: Advanced | D8: Core | E8: Hanging core, 4 sets. Team stretch. | F8: 7:45-8:00 PM | H8: EXAMPLE | I8: =IF($A8="","",IF($A8='Day View'!$B$4,COUNTIFS($A$5:$A8,'Day View'!$B$4),""))
D9: =IFERROR(INDEX('Exercise Library'!$B$6:$B$120,MATCH(C9,ExerciseNames,0)),"") | E9: =IFERROR(INDEX('Exercise Library'!$E$6:$E$120,MATCH(C9,ExerciseNames,0)),"") | F9: =IFERROR(INDEX('Exercise Library'!$F$6:$F$120,MATCH(C9,ExerciseNames,0)),"") | I9: =IF($A9="","",IF($A9='Day View'!$B$4,COUNTIFS($A$5:$A9,'Day View'!$B$4),""))
D10: =IFERROR(INDEX('Exercise Library'!$B$6:$B$120,MATCH(C10,ExerciseNames,0)),"") | E10: =IFERROR(INDEX('Exercise Library'!$E$6:$E$120,MATCH(C10,ExerciseNames,0)),"") | F10: =IFERROR(INDEX('Exercise Library'!$F$6:$F$120,MATCH(C10,ExerciseNames,0)),"") | I10: =IF($A10="","",IF($A10='Day View'!$B$4,COUNTIFS($A$5:$A10,'Day View'!$B$4),""))
D11: =IFERROR(INDEX('Exercise Library'!$B$6:$B$120,MATCH(C11,ExerciseNames,0)),"") | E11: =IFERROR(INDEX('Exercise Library'!$E$6:$E$120,MATCH(C11,ExerciseNames,0)),"") | F11: =IFERROR(INDEX('Exercise Library'!$F$6:$F$120,MATCH(C11,ExerciseNames,0)),"") | I11: =IF($A11="","",IF($A11='Day View'!$B$4,COUNTIFS($A$5:$A11,'Day View'!$B$4),""))
D12: =IFERROR(INDEX('Exercise Library'!$B$6:$B$120,MATCH(C12,ExerciseNames,0)),"") | E12: =IFERROR(INDEX('Exercise Library'!$E$6:$E$120,MATCH(C12,ExerciseNames,0)),"") | F12: =IFERROR(INDEX('Exercise Library'!$F$6:$F$120,MATCH(C12,ExerciseNames,0)),"") | I12: =IF($A12="","",IF($A12='Day View'!$B$4,COUNTIFS($A$5:$A12,'Day View'!$B$4),""))
D13: =IFERROR(INDEX('Exercise Library'!$B$6:$B$120,MATCH(C13,ExerciseNames,0)),"") | E13: =IFERROR(INDEX('Exercise Library'!$E$6:$E$120,MATCH(C13,ExerciseNames,0)),"") | F13: =IFERROR(INDEX('Exercise Library'!$F$6:$F$120,MATCH(C13,ExerciseNames,0)),"") | I13: =IF($A13="","",IF($A13='Day View'!$B$4,COUNTIFS($A$5:$A13,'Day View'!$B$4),""))
D14: =IFERROR(INDEX('Exercise Library'!$B$6:$B$120,MATCH(C14,ExerciseNames,0)),"") | E14: =IFERROR(INDEX('Exercise Library'!$E$6:$E$120,MATCH(C14,ExerciseNames,0)),"") | F14: =IFERROR(INDEX('Exercise Library'!$F$6:$F$120,MATCH(C14,ExerciseNames,0)),"") | I14: =IF($A14="","",IF($A14='Day View'!$B$4,COUNTIFS($A$5:$A14,'Day View'!$B$4),""))
D15: =IFERROR(INDEX('Exercise Library'!$B$6:$B$120,MATCH(C15,ExerciseNames,0)),"") | E15: =IFERROR(INDEX('Exercise Library'!$E$6:$E$120,MATCH(C15,ExerciseNames,0)),"") | F15: =IFERROR(INDEX('Exercise Library'!$F$6:$F$120,MATCH(C15,ExerciseNames,0)),"") | I15: =IF($A15="","",IF($A15='Day View'!$B$4,COUNTIFS($A$5:$A15,'Day View'!$B$4),""))
D16: =IFERROR(INDEX('Exercise Library'!$B$6:$B$120,MATCH(C16,ExerciseNames,0)),"") | E16: =IFERROR(INDEX('Exercise Library'!$E$6:$E$120,MATCH(C16,ExerciseNames,0)),"") | F16: =IFERROR(INDEX('Exercise Library'!$F$6:$F$120,MATCH(C16,ExerciseNames,0)),"") | I16: =IF($A16="","",IF($A16='Day View'!$B$4,COUNTIFS($A$5:$A16,'Day View'!$B$4),""))
D17: =IFERROR(INDEX('Exercise Library'!$B$6:$B$120,MATCH(C17,ExerciseNames,0)),"") | E17: =IFERROR(INDEX('Exercise Library'!$E$6:$E$120,MATCH(C17,ExerciseNames,0)),"") | F17: =IFERROR(INDEX('Exercise Library'!$F$6:$F$120,MATCH(C17,ExerciseNames,0)),"") | I17: =IF($A17="","",IF($A17='Day View'!$B$4,COUNTIFS($A$5:$A17,'Day View'!$B$4),""))
D18: =IFERROR(INDEX('Exercise Library'!$B$6:$B$120,MATCH(C18,ExerciseNames,0)),"") | E18: =IFERROR(INDEX('Exercise Library'!$E$6:$E$120,MATCH(C18,ExerciseNames,0)),"") | F18: =IFERROR(INDEX('Exercise Library'!$F$6:$F$120,MATCH(C18,ExerciseNames,0)),"") | I18: =IF($A18="","",IF($A18='Day View'!$B$4,COUNTIFS($A$5:$A18,'Day View'!$B$4),""))
D19: =IFERROR(INDEX('Exercise Library'!$B$6:$B$120,MATCH(C19,ExerciseNames,0)),"") | E19: =IFERROR(INDEX('Exercise Library'!$E$6:$E$120,MATCH(C19,ExerciseNames,0)),"") | F19: =IFERROR(INDEX('Exercise Library'!$F$6:$F$120,MATCH(C19,ExerciseNames,0)),"") | I19: =IF($A19="","",IF($A19='Day View'!$B$4,COUNTIFS($A$5:$A19,'Day View'!$B$4),""))
D20: =IFERROR(INDEX('Exercise Library'!$B$6:$B$120,MATCH(C20,ExerciseNames,0)),"") | E20: =IFERROR(INDEX('Exercise Library'!$E$6:$E$120,MATCH(C20,ExerciseNames,0)),"") | F20: =IFERROR(INDEX('Exercise Library'!$F$6:$F$120,MATCH(C20,ExerciseNames,0)),"") | I20: =IF($A20="","",IF($A20='Day View'!$B$4,COUNTIFS($A$5:$A20,'Day View'!$B$4),""))
... D200: =IFERROR(INDEX('Exercise Library'!$B$6:$B$120,MATCH(C200,ExerciseNames,0)),"") | E200: =IFERROR(INDEX('Exercise Library'!$E$6:$E$120,MATCH(C200,ExerciseNames,0)),"") | F200: =IFERROR(INDEX('Exercise Library'!$F$6:$F$120,MATCH(C200,ExerciseNames,0)),"") | I200: =IF($A200="","",IF($A200='Day View'!$B$4,COUNTIFS($A$5:$A200,'Day View'!$B$4),""))

Sheet Day View
A1: Day View
A2: Pick a date, scroll down. Built to read top-to-bottom on a phone — nothing to scroll sideways for.
A3: Today: | B3: FALSE | C3: tap TRUE
A4: Date: | B4: =TODAY()
A5: ="Coaches: "&IFERROR(INDEX('Full Team Calendar'!$C$5:$C$52,MATCH($B$4,'Full Team Calendar'!$A$5:$A$52,0)),"—")&" • Featured tier: "&IFERROR(INDEX('Full Team Calendar'!$D$5:$D$52,MATCH($B$4,'Full Team Calendar'!$A$5:$A$52,0)),"—")
A6: ⚠ Clear plan: | B6: FALSE | C6: wipes everything below, no undo
A7: =IF(SUMPRODUCT(--(LogDayRank<>""))=0,"Nothing logged for this date yet — open Log a Workout to add it.",SUMPRODUCT(--(LogDayRank<>""))&" block(s) planned:")
A9: =IF($F9="","",$G9&" — "&$H9) | F9: =IFERROR(MATCH(1,LogDayRank,0),"") | G9: =IFERROR(IF(INDEX('Log a Workout'!$B$5:$B$200,$F9)=0,"",INDEX('Log a Workout'!$B$5:$B$200,$F9)),"") | H9: =IFERROR(IF(INDEX('Log a Workout'!$D$5:$D$200,$F9)=0,"",INDEX('Log a Workout'!$D$5:$D$200,$F9)),"") | J9: =IFERROR(IF(INDEX('Log a Workout'!$E$5:$E$200,$F9)=0,"",INDEX('Log a Workout'!$E$5:$E$200,$F9)),"") | K9: =IFERROR(IF(INDEX('Log a Workout'!$F$5:$F$200,$F9)=0,"",INDEX('Log a Workout'!$F$5:$F$200,$F9)),"") | L9: =IFERROR(IF(INDEX('Log a Workout'!$G$5:$G$200,$F9)=0,"",INDEX('Log a Workout'!$G$5:$G$200,$F9)),"") | M9: =IFERROR(IF(INDEX('Log a Workout'!$H$5:$H$200,$F9)=0,"",INDEX('Log a Workout'!$H$5:$H$200,$F9)),"")
A10: =$J9
A11: =TRIM($K9&IF(AND($K9<>"",$L9<>"")," • ","")&IF($L9<>"","Coach: "&$L9,"")&IF(AND(OR($K9<>"",$L9<>""),$M9<>"")," • ","")&$M9)
A12: =IF($F12="","",$G12&" — "&$H12) | F12: =IFERROR(MATCH(2,LogDayRank,0),"") | G12: =IFERROR(IF(INDEX('Log a Workout'!$B$5:$B$200,$F12)=0,"",INDEX('Log a Workout'!$B$5:$B$200,$F12)),"") | H12: =IFERROR(IF(INDEX('Log a Workout'!$D$5:$D$200,$F12)=0,"",INDEX('Log a Workout'!$D$5:$D$200,$F12)),"") | J12: =IFERROR(IF(INDEX('Log a Workout'!$E$5:$E$200,$F12)=0,"",INDEX('Log a Workout'!$E$5:$E$200,$F12)),"") | K12: =IFERROR(IF(INDEX('Log a Workout'!$F$5:$F$200,$F12)=0,"",INDEX('Log a Workout'!$F$5:$F$200,$F12)),"") | L12: =IFERROR(IF(INDEX('Log a Workout'!$G$5:$G$200,$F12)=0,"",INDEX('Log a Workout'!$G$5:$G$200,$F12)),"") | M12: =IFERROR(IF(INDEX('Log a Workout'!$H$5:$H$200,$F12)=0,"",INDEX('Log a Workout'!$H$5:$H$200,$F12)),"")
A13: =$J12
A14: =TRIM($K12&IF(AND($K12<>"",$L12<>"")," • ","")&IF($L12<>"","Coach: "&$L12,"")&IF(AND(OR($K12<>"",$L12<>""),$M12<>"")," • ","")&$M12)
A15: =IF($F15="","",$G15&" — "&$H15) | F15: =IFERROR(MATCH(3,LogDayRank,0),"") | G15: =IFERROR(IF(INDEX('Log a Workout'!$B$5:$B$200,$F15)=0,"",INDEX('Log a Workout'!$B$5:$B$200,$F15)),"") | H15: =IFERROR(IF(INDEX('Log a Workout'!$D$5:$D$200,$F15)=0,"",INDEX('Log a Workout'!$D$5:$D$200,$F15)),"") | J15: =IFERROR(IF(INDEX('Log a Workout'!$E$5:$E$200,$F15)=0,"",INDEX('Log a Workout'!$E$5:$E$200,$F15)),"") | K15: =IFERROR(IF(INDEX('Log a Workout'!$F$5:$F$200,$F15)=0,"",INDEX('Log a Workout'!$F$5:$F$200,$F15)),"") | L15: =IFERROR(IF(INDEX('Log a Workout'!$G$5:$G$200,$F15)=0,"",INDEX('Log a Workout'!$G$5:$G$200,$F15)),"") | M15: =IFERROR(IF(INDEX('Log a Workout'!$H$5:$H$200,$F15)=0,"",INDEX('Log a Workout'!$H$5:$H$200,$F15)),"")
A16: =$J15
A17: =TRIM($K15&IF(AND($K15<>"",$L15<>"")," • ","")&IF($L15<>"","Coach: "&$L15,"")&IF(AND(OR($K15<>"",$L15<>""),$M15<>"")," • ","")&$M15)
A18: =IF($F18="","",$G18&" — "&$H18) | F18: =IFERROR(MATCH(4,LogDayRank,0),"") | G18: =IFERROR(IF(INDEX('Log a Workout'!$B$5:$B$200,$F18)=0,"",INDEX('Log a Workout'!$B$5:$B$200,$F18)),"") | H18: =IFERROR(IF(INDEX('Log a Workout'!$D$5:$D$200,$F18)=0,"",INDEX('Log a Workout'!$D$5:$D$200,$F18)),"") | J18: =IFERROR(IF(INDEX('Log a Workout'!$E$5:$E$200,$F18)=0,"",INDEX('Log a Workout'!$E$5:$E$200,$F18)),"") | K18: =IFERROR(IF(INDEX('Log a Workout'!$F$5:$F$200,$F18)=0,"",INDEX('Log a Workout'!$F$5:$F$200,$F18)),"") | L18: =IFERROR(IF(INDEX('Log a Workout'!$G$5:$G$200,$F18)=0,"",INDEX('Log a Workout'!$G$5:$G$200,$F18)),"") | M18: =IFERROR(IF(INDEX('Log a Workout'!$H$5:$H$200,$F18)=0,"",INDEX('Log a Workout'!$H$5:$H$200,$F18)),"")
A19: =$J18
A20: =TRIM($K18&IF(AND($K18<>"",$L18<>"")," • ","")&IF($L18<>"","Coach: "&$L18,"")&IF(AND(OR($K18<>"",$L18<>""),$M18<>"")," • ","")&$M18)
A21: =IF($F21="","",$G21&" — "&$H21) | F21: =IFERROR(MATCH(5,LogDayRank,0),"") | G21: =IFERROR(IF(INDEX('Log a Workout'!$B$5:$B$200,$F21)=0,"",INDEX('Log a Workout'!$B$5:$B$200,$F21)),"") | H21: =IFERROR(IF(INDEX('Log a Workout'!$D$5:$D$200,$F21)=0,"",INDEX('Log a Workout'!$D$5:$D$200,$F21)),"") | J21: =IFERROR(IF(INDEX('Log a Workout'!$E$5:$E$200,$F21)=0,"",INDEX('Log a Workout'!$E$5:$E$200,$F21)),"") | K21: =IFERROR(IF(INDEX('Log a Workout'!$F$5:$F$200,$F21)=0,"",INDEX('Log a Workout'!$F$5:$F$200,$F21)),"") | L21: =IFERROR(IF(INDEX('Log a Workout'!$G$5:$G$200,$F21)=0,"",INDEX('Log a Workout'!$G$5:$G$200,$F21)),"") | M21: =IFERROR(IF(INDEX('Log a Workout'!$H$5:$H$200,$F21)=0,"",INDEX('Log a Workout'!$H$5:$H$200,$F21)),"")
A22: =$J21
A23: =TRIM($K21&IF(AND($K21<>"",$L21<>"")," • ","")&IF($L21<>"","Coach: "&$L21,"")&IF(AND(OR($K21<>"",$L21<>""),$M21<>"")," • ","")&$M21)
A24: =IF($F24="","",$G24&" — "&$H24) | F24: =IFERROR(MATCH(6,LogDayRank,0),"") | G24: =IFERROR(IF(INDEX('Log a Workout'!$B$5:$B$200,$F24)=0,"",INDEX('Log a Workout'!$B$5:$B$200,$F24)),"") | H24: =IFERROR(IF(INDEX('Log a Workout'!$D$5:$D$200,$F24)=0,"",INDEX('Log a Workout'!$D$5:$D$200,$F24)),"") | J24: =IFERROR(IF(INDEX('Log a Workout'!$E$5:$E$200,$F24)=0,"",INDEX('Log a Workout'!$E$5:$E$200,$F24)),"") | K24: =IFERROR(IF(INDEX('Log a Workout'!$F$5:$F$200,$F24)=0,"",INDEX('Log a Workout'!$F$5:$F$200,$F24)),"") | L24: =IFERROR(IF(INDEX('Log a Workout'!$G$5:$G$200,$F24)=0,"",INDEX('Log a Workout'!$G$5:$G$200,$F24)),"") | M24: =IFERROR(IF(INDEX('Log a Workout'!$H$5:$H$200,$F24)=0,"",INDEX('Log a Workout'!$H$5:$H$200,$F24)),"")
A25: =$J24
A26: =TRIM($K24&IF(AND($K24<>"",$L24<>"")," • ","")&IF($L24<>"","Coach: "&$L24,"")&IF(AND(OR($K24<>"",$L24<>""),$M24<>"")," • ","")&$M24)
A27: =IF($F27="","",$G27&" — "&$H27) | F27: =IFERROR(MATCH(7,LogDayRank,0),"") | G27: =IFERROR(IF(INDEX('Log a Workout'!$B$5:$B$200,$F27)=0,"",INDEX('Log a Workout'!$B$5:$B$200,$F27)),"") | H27: =IFERROR(IF(INDEX('Log a Workout'!$D$5:$D$200,$F27)=0,"",INDEX('Log a Workout'!$D$5:$D$200,$F27)),"") | J27: =IFERROR(IF(INDEX('Log a Workout'!$E$5:$E$200,$F27)=0,"",INDEX('Log a Workout'!$E$5:$E$200,$F27)),"") | K27: =IFERROR(IF(INDEX('Log a Workout'!$F$5:$F$200,$F27)=0,"",INDEX('Log a Workout'!$F$5:$F$200,$F27)),"") | L27: =IFERROR(IF(INDEX('Log a Workout'!$G$5:$G$200,$F27)=0,"",INDEX('Log a Workout'!$G$5:$G$200,$F27)),"") | M27: =IFERROR(IF(INDEX('Log a Workout'!$H$5:$H$200,$F27)=0,"",INDEX('Log a Workout'!$H$5:$H$200,$F27)),"")
A28: =$J27
A29: =TRIM($K27&IF(AND($K27<>"",$L27<>"")," • ","")&IF($L27<>"","Coach: "&$L27,"")&IF(AND(OR($K27<>"",$L27<>""),$M27<>"")," • ","")&$M27)
A30: =IF($F30="","",$G30&" — "&$H30) | F30: =IFERROR(MATCH(8,LogDayRank,0),"") | G30: =IFERROR(IF(INDEX('Log a Workout'!$B$5:$B$200,$F30)=0,"",INDEX('Log a Workout'!$B$5:$B$200,$F30)),"") | H30: =IFERROR(IF(INDEX('Log a Workout'!$D$5:$D$200,$F30)=0,"",INDEX('Log a Workout'!$D$5:$D$200,$F30)),"") | J30: =IFERROR(IF(INDEX('Log a Workout'!$E$5:$E$200,$F30)=0,"",INDEX('Log a Workout'!$E$5:$E$200,$F30)),"") | K30: =IFERROR(IF(INDEX('Log a Workout'!$F$5:$F$200,$F30)=0,"",INDEX('Log a Workout'!$F$5:$F$200,$F30)),"") | L30: =IFERROR(IF(INDEX('Log a Workout'!$G$5:$G$200,$F30)=0,"",INDEX('Log a Workout'!$G$5:$G$200,$F30)),"") | M30: =IFERROR(IF(INDEX('Log a Workout'!$H$5:$H$200,$F30)=0,"",INDEX('Log a Workout'!$H$5:$H$200,$F30)),"")
A31: =$J30
A32: =TRIM($K30&IF(AND($K30<>"",$L30<>"")," • ","")&IF($L30<>"","Coach: "&$L30,"")&IF(AND(OR($K30<>"",$L30<>""),$M30<>"")," • ","")&$M30)
A33: =IF($F33="","",$G33&" — "&$H33) | F33: =IFERROR(MATCH(9,LogDayRank,0),"") | G33: =IFERROR(IF(INDEX('Log a Workout'!$B$5:$B$200,$F33)=0,"",INDEX('Log a Workout'!$B$5:$B$200,$F33)),"") | H33: =IFERROR(IF(INDEX('Log a Workout'!$D$5:$D$200,$F33)=0,"",INDEX('Log a Workout'!$D$5:$D$200,$F33)),"") | J33: =IFERROR(IF(INDEX('Log a Workout'!$E$5:$E$200,$F33)=0,"",INDEX('Log a Workout'!$E$5:$E$200,$F33)),"") | K33: =IFERROR(IF(INDEX('Log a Workout'!$F$5:$F$200,$F33)=0,"",INDEX('Log a Workout'!$F$5:$F$200,$F33)),"") | L33: =IFERROR(IF(INDEX('Log a Workout'!$G$5:$G$200,$F33)=0,"",INDEX('Log a Workout'!$G$5:$G$200,$F33)),"") | M33: =IFERROR(IF(INDEX('Log a Workout'!$H$5:$H$200,$F33)=0,"",INDEX('Log a Workout'!$H$5:$H$200,$F33)),"")
A34: =$J33
A35: =TRIM($K33&IF(AND($K33<>"",$L33<>"")," • ","")&IF($L33<>"","Coach: "&$L33,"")&IF(AND(OR($K33<>"",$L33<>""),$M33<>"")," • ","")&$M33)
A36: =IF($F36="","",$G36&" — "&$H36) | F36: =IFERROR(MATCH(10,LogDayRank,0),"") | G36: =IFERROR(IF(INDEX('Log a Workout'!$B$5:$B$200,$F36)=0,"",INDEX('Log a Workout'!$B$5:$B$200,$F36)),"") | H36: =IFERROR(IF(INDEX('Log a Workout'!$D$5:$D$200,$F36)=0,"",INDEX('Log a Workout'!$D$5:$D$200,$F36)),"") | J36: =IFERROR(IF(INDEX('Log a Workout'!$E$5:$E$200,$F36)=0,"",INDEX('Log a Workout'!$E$5:$E$200,$F36)),"") | K36: =IFERROR(IF(INDEX('Log a Workout'!$F$5:$F$200,$F36)=0,"",INDEX('Log a Workout'!$F$5:$F$200,$F36)),"") | L36: =IFERROR(IF(INDEX('Log a Workout'!$G$5:$G$200,$F36)=0,"",INDEX('Log a Workout'!$G$5:$G$200,$F36)),"") | M36: =IFERROR(IF(INDEX('Log a Workout'!$H$5:$H$200,$F36)=0,"",INDEX('Log a Workout'!$H$5:$H$200,$F36)),"")
A37: =$J36
A38: =TRIM($K36&IF(AND($K36<>"",$L36<>"")," • ","")&IF($L36<>"","Coach: "&$L36,"")&IF(AND(OR($K36<>"",$L36<>""),$M36<>"")," • ","")&$M36)
A39: =IF($F39="","",$G39&" — "&$H39) | F39: =IFERROR(MATCH(11,LogDayRank,0),"") | G39: =IFERROR(IF(INDEX('Log a Workout'!$B$5:$B$200,$F39)=0,"",INDEX('Log a Workout'!$B$5:$B$200,$F39)),"") | H39: =IFERROR(IF(INDEX('Log a Workout'!$D$5:$D$200,$F39)=0,"",INDEX('Log a Workout'!$D$5:$D$200,$F39)),"") | J39: =IFERROR(IF(INDEX('Log a Workout'!$E$5:$E$200,$F39)=0,"",INDEX('Log a Workout'!$E$5:$E$200,$F39)),"") | K39: =IFERROR(IF(INDEX('Log a Workout'!$F$5:$F$200,$F39)=0,"",INDEX('Log a Workout'!$F$5:$F$200,$F39)),"") | L39: =IFERROR(IF(INDEX('Log a Workout'!$G$5:$G$200,$F39)=0,"",INDEX('Log a Workout'!$G$5:$G$200,$F39)),"") | M39: =IFERROR(IF(INDEX('Log a Workout'!$H$5:$H$200,$F39)=0,"",INDEX('Log a Workout'!$H$5:$H$200,$F39)),"")
A40: =$J39
A41: =TRIM($K39&IF(AND($K39<>"",$L39<>"")," • ","")&IF($L39<>"","Coach: "&$L39,"")&IF(AND(OR($K39<>"",$L39<>""),$M39<>"")," • ","")&$M39)
...

Sheet Athlete Profiles
A1: Athlete Profiles
A2: The whole roster, one row per athlete. Type straight into a blank row below to add someone — works on a phone, no menu needed. Tap the checkbox in row 4 to jump to the next open row. Color = tier (set in Settings). Use Data > Create a filter to see one tier at a time.
A3: Counts (auto): | B3: =Settings!$B$5&": "&COUNTIF($F$6:$F$200,Settings!$B$5) | D3: =Settings!$B$6&": "&COUNTIF($F$6:$F$200,Settings!$B$6) | F3: =Settings!$B$7&": "&COUNTIF($F$6:$F$200,Settings!$B$7) | H3: ="Total: "&COUNTA($B$6:$B$200)
A4: New: | B4: FALSE | C4: tap TRUE to jump to the next open row
A5: ID | B5: First Name | C5: Last Name | D5: Full Name | E5: Age | F5: Group | G5: Current Flash Grade | H5: Goal Grade | I5: Strengths | J5: Growth Areas | K5: Current Focus / Goal | L5: Join Date | M5: Status | N5: Notes | O5: ⚠ Delete?
A6: =IF(B6="","",ROW()-5) | B6: Alex | C6: Rivera | D6: =IF(B6="","",TRIM(B6&" "&C6)) | E6: 13 | F6: Advanced | G6: V6 | H6: V8 | I6: Big power moves, competition composure | J6: Foot precision on slab | K6: Qualify for divisionals | L6: 45170 | M6: Active | N6: EXAMPLE ROW — overwrite or delete | O6: FALSE
A7: =IF(B7="","",ROW()-5) | B7: Sam | C7: Nguyen | D7: =IF(B7="","",TRIM(B7&" "&C7)) | E7: 10 | F7: Developing | G7: V1 | H7: V3 | I7: Enthusiasm, coordination drills | J7: Confidence on lead/overhang | K7: Stick 3 moves in a row without a pause | L7: 45672 | M7: Active | N7: EXAMPLE ROW — overwrite or delete | O7: FALSE
A8: =IF(B8="","",ROW()-5) | D8: =IF(B8="","",TRIM(B8&" "&C8)) | O8: FALSE
A9: =IF(B9="","",ROW()-5) | D9: =IF(B9="","",TRIM(B9&" "&C9)) | O9: FALSE
A10: =IF(B10="","",ROW()-5) | D10: =IF(B10="","",TRIM(B10&" "&C10)) | O10: FALSE
A11: =IF(B11="","",ROW()-5) | D11: =IF(B11="","",TRIM(B11&" "&C11)) | O11: FALSE
A12: =IF(B12="","",ROW()-5) | D12: =IF(B12="","",TRIM(B12&" "&C12)) | O12: FALSE
A13: =IF(B13="","",ROW()-5) | D13: =IF(B13="","",TRIM(B13&" "&C13)) | O13: FALSE
A14: =IF(B14="","",ROW()-5) | D14: =IF(B14="","",TRIM(B14&" "&C14)) | O14: FALSE
A15: =IF(B15="","",ROW()-5) | D15: =IF(B15="","",TRIM(B15&" "&C15)) | O15: FALSE
A16: =IF(B16="","",ROW()-5) | D16: =IF(B16="","",TRIM(B16&" "&C16)) | O16: FALSE
A17: =IF(B17="","",ROW()-5) | D17: =IF(B17="","",TRIM(B17&" "&C17)) | O17: FALSE
A18: =IF(B18="","",ROW()-5) | D18: =IF(B18="","",TRIM(B18&" "&C18)) | O18: FALSE
A19: =IF(B19="","",ROW()-5) | D19: =IF(B19="","",TRIM(B19&" "&C19)) | O19: FALSE
... A37: =IF(B37="","",ROW()-5) | D37: =IF(B37="","",TRIM(B37&" "&C37)) | O37: FALSE

Sheet Coach Profiles
A1: Coach Profiles
A2: One row per coach, for any day they coach. Type straight into a blank row below to add someone — works on a phone, no menu needed. Tap the checkbox in row 4 to jump to the next open row. Flag which day(s) each coach works — Full Team Calendar and Rotation Schedule pull from these flags automatically, in row order, to rotate lead-coach duty.
A3: Counts (auto): | B3: ="Mon: "&SUMPRODUCT(--(MondayCoachList<>"")) | D3: ="Tue: "&SUMPRODUCT(--(TuesdayCoachList<>"")) | F3: ="Thu: "&SUMPRODUCT(--(ThursdayCoachList<>"")) | H3: ="Total: "&COUNTA($B$6:$B$19)
A4: New: | B4: FALSE | C4: tap TRUE to jump to the next open row
A5: ID | B5: First Name | C5: Last Name | D5: Full Name | E5: Role | F5: Mon? | G5: Tue? | H5: Thu? | I5: Other Days | J5: Email | K5: Phone | L5: Specialties / Certifications | M5: Bio / Notes | N5: Status | P5: Mon Rk | Q5: Tue Rk | R5: Thu Rk | T5: Monday order | U5: Tuesday order | V5: Thursday order | W5: ⚠ Delete?
A6: =IF(B6="","",ROW()-5) | B6: Jordan | C6: Lee | D6: =IF(B6="","",TRIM(B6&" "&C6)) | E6: Head Coach | F6: Yes | G6: Yes | H6: No | J6: jordan@example.com | K6: (555) 010-2231 | L6: USAC Level 2, Youth Development | M6: Leads Monday & Tuesday team practices. | N6: Active | P6: =IF(AND($F6="Yes",$N6="Active"),COUNTIFS($F$6:$F6,"Yes",$N$6:$N6,"Active"),"") | Q6: =IF(AND($G6="Yes",$N6="Active"),COUNTIFS($G$6:$G6,"Yes",$N$6:$N6,"Active"),"") | R6: =IF(AND($H6="Yes",$N6="Active"),COUNTIFS($H$6:$H6,"Yes",$N$6:$N6,"Active"),"") | T6: =IFERROR(INDEX($D$6:$D$19,MATCH(1,$P$6:$P$19,0)),"") | U6: =IFERROR(INDEX($D$6:$D$19,MATCH(1,$Q$6:$Q$19,0)),"") | V6: =IFERROR(INDEX($D$6:$D$19,MATCH(1,$R$6:$R$19,0)),"") | W6: FALSE
A7: =IF(B7="","",ROW()-5) | B7: Taylor | C7: Brooks | D7: =IF(B7="","",TRIM(B7&" "&C7)) | E7: Coach | F7: No | G7: No | H7: Yes | J7: taylor@example.com | K7: (555) 010-4470 | L7: Youth coordination, competition prep | M7: Plans and leads the Thursday tiered block. | N7: Active | P7: =IF(AND($F7="Yes",$N7="Active"),COUNTIFS($F$6:$F7,"Yes",$N$6:$N7,"Active"),"") | Q7: =IF(AND($G7="Yes",$N7="Active"),COUNTIFS($G$6:$G7,"Yes",$N$6:$N7,"Active"),"") | R7: =IF(AND($H7="Yes",$N7="Active"),COUNTIFS($H$6:$H7,"Yes",$N$6:$N7,"Active"),"") | T7: =IFERROR(INDEX($D$6:$D$19,MATCH(2,$P$6:$P$19,0)),"") | U7: =IFERROR(INDEX($D$6:$D$19,MATCH(2,$Q$6:$Q$19,0)),"") | V7: =IFERROR(INDEX($D$6:$D$19,MATCH(2,$R$6:$R$19,0)),"") | W7: FALSE
A8: =IF(B8="","",ROW()-5) | D8: =IF(B8="","",TRIM(B8&" "&C8)) | P8: =IF(AND($F8="Yes",$N8="Active"),COUNTIFS($F$6:$F8,"Yes",$N$6:$N8,"Active"),"") | Q8: =IF(AND($G8="Yes",$N8="Active"),COUNTIFS($G$6:$G8,"Yes",$N$6:$N8,"Active"),"") | R8: =IF(AND($H8="Yes",$N8="Active"),COUNTIFS($H$6:$H8,"Yes",$N$6:$N8,"Active"),"") | T8: =IFERROR(INDEX($D$6:$D$19,MATCH(3,$P$6:$P$19,0)),"") | U8: =IFERROR(INDEX($D$6:$D$19,MATCH(3,$Q$6:$Q$19,0)),"") | V8: =IFERROR(INDEX($D$6:$D$19,MATCH(3,$R$6:$R$19,0)),"") | W8: FALSE
A9: =IF(B9="","",ROW()-5) | D9: =IF(B9="","",TRIM(B9&" "&C9)) | P9: =IF(AND($F9="Yes",$N9="Active"),COUNTIFS($F$6:$F9,"Yes",$N$6:$N9,"Active"),"") | Q9: =IF(AND($G9="Yes",$N9="Active"),COUNTIFS($G$6:$G9,"Yes",$N$6:$N9,"Active"),"") | R9: =IF(AND($H9="Yes",$N9="Active"),COUNTIFS($H$6:$H9,"Yes",$N$6:$N9,"Active"),"") | T9: =IFERROR(INDEX($D$6:$D$19,MATCH(4,$P$6:$P$19,0)),"") | U9: =IFERROR(INDEX($D$6:$D$19,MATCH(4,$Q$6:$Q$19,0)),"") | V9: =IFERROR(INDEX($D$6:$D$19,MATCH(4,$R$6:$R$19,0)),"") | W9: FALSE
A10: =IF(B10="","",ROW()-5) | D10: =IF(B10="","",TRIM(B10&" "&C10)) | P10: =IF(AND($F10="Yes",$N10="Active"),COUNTIFS($F$6:$F10,"Yes",$N$6:$N10,"Active"),"") | Q10: =IF(AND($G10="Yes",$N10="Active"),COUNTIFS($G$6:$G10,"Yes",$N$6:$N10,"Active"),"") | R10: =IF(AND($H10="Yes",$N10="Active"),COUNTIFS($H$6:$H10,"Yes",$N$6:$N10,"Active"),"") | T10: =IFERROR(INDEX($D$6:$D$19,MATCH(5,$P$6:$P$19,0)),"") | U10: =IFERROR(INDEX($D$6:$D$19,MATCH(5,$Q$6:$Q$19,0)),"") | V10: =IFERROR(INDEX($D$6:$D$19,MATCH(5,$R$6:$R$19,0)),"") | W10: FALSE
A11: =IF(B11="","",ROW()-5) | D11: =IF(B11="","",TRIM(B11&" "&C11)) | P11: =IF(AND($F11="Yes",$N11="Active"),COUNTIFS($F$6:$F11,"Yes",$N$6:$N11,"Active"),"") | Q11: =IF(AND($G11="Yes",$N11="Active"),COUNTIFS($G$6:$G11,"Yes",$N$6:$N11,"Active"),"") | R11: =IF(AND($H11="Yes",$N11="Active"),COUNTIFS($H$6:$H11,"Yes",$N$6:$N11,"Active"),"") | T11: =IFERROR(INDEX($D$6:$D$19,MATCH(6,$P$6:$P$19,0)),"") | U11: =IFERROR(INDEX($D$6:$D$19,MATCH(6,$Q$6:$Q$19,0)),"") | V11: =IFERROR(INDEX($D$6:$D$19,MATCH(6,$R$6:$R$19,0)),"") | W11: FALSE
A12: =IF(B12="","",ROW()-5) | D12: =IF(B12="","",TRIM(B12&" "&C12)) | P12: =IF(AND($F12="Yes",$N12="Active"),COUNTIFS($F$6:$F12,"Yes",$N$6:$N12,"Active"),"") | Q12: =IF(AND($G12="Yes",$N12="Active"),COUNTIFS($G$6:$G12,"Yes",$N$6:$N12,"Active"),"") | R12: =IF(AND($H12="Yes",$N12="Active"),COUNTIFS($H$6:$H12,"Yes",$N$6:$N12,"Active"),"") | T12: =IFERROR(INDEX($D$6:$D$19,MATCH(7,$P$6:$P$19,0)),"") | U12: =IFERROR(INDEX($D$6:$D$19,MATCH(7,$Q$6:$Q$19,0)),"") | V12: =IFERROR(INDEX($D$6:$D$19,MATCH(7,$R$6:$R$19,0)),"") | W12: FALSE
A13: =IF(B13="","",ROW()-5) | D13: =IF(B13="","",TRIM(B13&" "&C13)) | P13: =IF(AND($F13="Yes",$N13="Active"),COUNTIFS($F$6:$F13,"Yes",$N$6:$N13,"Active"),"") | Q13: =IF(AND($G13="Yes",$N13="Active"),COUNTIFS($G$6:$G13,"Yes",$N$6:$N13,"Active"),"") | R13: =IF(AND($H13="Yes",$N13="Active"),COUNTIFS($H$6:$H13,"Yes",$N$6:$N13,"Active"),"") | T13: =IFERROR(INDEX($D$6:$D$19,MATCH(8,$P$6:$P$19,0)),"") | U13: =IFERROR(INDEX($D$6:$D$19,MATCH(8,$Q$6:$Q$19,0)),"") | V13: =IFERROR(INDEX($D$6:$D$19,MATCH(8,$R$6:$R$19,0)),"") | W13: FALSE
A14: =IF(B14="","",ROW()-5) | D14: =IF(B14="","",TRIM(B14&" "&C14)) | P14: =IF(AND($F14="Yes",$N14="Active"),COUNTIFS($F$6:$F14,"Yes",$N$6:$N14,"Active"),"") | Q14: =IF(AND($G14="Yes",$N14="Active"),COUNTIFS($G$6:$G14,"Yes",$N$6:$N14,"Active"),"") | R14: =IF(AND($H14="Yes",$N14="Active"),COUNTIFS($H$6:$H14,"Yes",$N$6:$N14,"Active"),"") | W14: FALSE
A15: =IF(B15="","",ROW()-5) | D15: =IF(B15="","",TRIM(B15&" "&C15)) | P15: =IF(AND($F15="Yes",$N15="Active"),COUNTIFS($F$6:$F15,"Yes",$N$6:$N15,"Active"),"") | Q15: =IF(AND($G15="Yes",$N15="Active"),COUNTIFS($G$6:$G15,"Yes",$N$6:$N15,"Active"),"") | R15: =IF(AND($H15="Yes",$N15="Active"),COUNTIFS($H$6:$H15,"Yes",$N$6:$N15,"Active"),"") | W15: FALSE
A16: =IF(B16="","",ROW()-5) | D16: =IF(B16="","",TRIM(B16&" "&C16)) | P16: =IF(AND($F16="Yes",$N16="Active"),COUNTIFS($F$6:$F16,"Yes",$N$6:$N16,"Active"),"") | Q16: =IF(AND($G16="Yes",$N16="Active"),COUNTIFS($G$6:$G16,"Yes",$N$6:$N16,"Active"),"") | R16: =IF(AND($H16="Yes",$N16="Active"),COUNTIFS($H$6:$H16,"Yes",$N$6:$N16,"Active"),"") | W16: FALSE
A17: =IF(B17="","",ROW()-5) | D17: =IF(B17="","",TRIM(B17&" "&C17)) | P17: =IF(AND($F17="Yes",$N17="Active"),COUNTIFS($F$6:$F17,"Yes",$N$6:$N17,"Active"),"") | Q17: =IF(AND($G17="Yes",$N17="Active"),COUNTIFS($G$6:$G17,"Yes",$N$6:$N17,"Active"),"") | R17: =IF(AND($H17="Yes",$N17="Active"),COUNTIFS($H$6:$H17,"Yes",$N$6:$N17,"Active"),"") | W17: FALSE
A18: =IF(B18="","",ROW()-5) | D18: =IF(B18="","",TRIM(B18&" "&C18)) | P18: =IF(AND($F18="Yes",$N18="Active"),COUNTIFS($F$6:$F18,"Yes",$N$6:$N18,"Active"),"") | Q18: =IF(AND($G18="Yes",$N18="Active"),COUNTIFS($G$6:$G18,"Yes",$N$6:$N18,"Active"),"") | R18: =IF(AND($H18="Yes",$N18="Active"),COUNTIFS($H$6:$H18,"Yes",$N$6:$N18,"Active"),"") | W18: FALSE
A19: =IF(B19="","",ROW()-5) | D19: =IF(B19="","",TRIM(B19&" "&C19)) | P19: =IF(AND($F19="Yes",$N19="Active"),COUNTIFS($F$6:$F19,"Yes",$N$6:$N19,"Active"),"") | Q19: =IF(AND($G19="Yes",$N19="Active"),COUNTIFS($G$6:$G19,"Yes",$N$6:$N19,"Active"),"") | R19: =IF(AND($H19="Yes",$N19="Active"),COUNTIFS($H$6:$H19,"Yes",$N$6:$N19,"Active"),"") | W19: FALSE

Sheet Exercise Library
A1: Exercise Library
A2: A growing catalog of workouts/blocks by type and tier. Log a Workout pulls from this list — add a new one any time by typing into a blank row below, works on a phone. Tap the checkbox in row 4 to jump to the next open row.
A3: Counts (auto): | B3: ="Warm-up: "&COUNTIF($B$6:$B$200,"Warm-up") | D3: ="Power: "&COUNTIF($B$6:$B$200,"Power") | F3: ="Strength: "&COUNTIF($B$6:$B$200,"Strength") | H3: ="Total: "&COUNTA($D$6:$D$200)
A4: New: | B4: FALSE | C4: tap TRUE to jump to the next open row
A5: ID | B5: Block Type | C5: Tier | D5: Workout / Exercise Name | E5: Description / Instructions | F5: Suggested Sets x Reps / Duration | G5: Equipment | H5: Notes / Source | I5: Times Used | J5: ⚠ Delete?
A6: =IF(D6="","",ROW()-5) | B6: Warm-up | C6: All Levels | D6: Full-Body Warm-Up | E6: General movement, light traverse, joint mobility. | F6: 15-20 min | G6: None | H6: Standard opener, every practice | I6: =COUNTIF('Log a Workout'!$C$5:$C$200,D6) | J6: FALSE
A7: =IF(D7="","",ROW()-5) | B7: Warm-up | C7: All Levels | D7: Ladder Drill | E7: Ladder 5 down / 10 down evens as a warm-up movement drill. | F7: 5-10 down per set | G7: Ladder wall/board | H7: From current plan | I7: =COUNTIF('Log a Workout'!$C$5:$C$200,D7) | J7: FALSE
A8: =IF(D8="","",ROW()-5) | B8: Power | C8: Advanced | D8: Campus Board Ladder | E8: Jump catches, 1-max, 1-minus-1/max, 1-8 fast, with box jumps between sets. | F8: Per current plan progression | G8: Campus board, plyo box | H8: From 9/15 plan | I8: =COUNTIF('Log a Workout'!$C$5:$C$200,D8) | J8: FALSE
A9: =IF(D9="","",ROW()-5) | B9: Power | C9: Advanced | D9: Boulder Eliminates | E9: Pick boulders just below flash limit; remove holds until moves no longer go. | F9: 15 min max per boulder | G9: Bouldering wall | H9: From 9/14 plan | I9: =COUNTIF('Log a Workout'!$C$5:$C$200,D9) | J9: FALSE
A10: =IF(D10="","",ROW()-5) | B10: Power | C10: Advanced | D10: Above-Limit Bouldering | E10: Two groups, 30 min; try each boulder ~10 min (3 boulders total). | F10: 30 min per group | G10: Bouldering wall | H10: From 8/31 plan | I10: =COUNTIF('Log a Workout'!$C$5:$C$200,D10) | J10: FALSE
A11: =IF(D11="","",ROW()-5) | B11: Power | C11: Intermediate | D11: 3-Move Power Boulders (Partner) | E11: Two coordination boulders (one hand, one foot) + two power moves; try, switch roles, repeat. | F11: Per pair, rotate roles | G11: Bouldering wall | H11: From 9/8 plan | I11: =COUNTIF('Log a Workout'!$C$5:$C$200,D11) | J11: FALSE
A12: =IF(D12="","",ROW()-5) | B12: Power | C12: Developing | D12: 3-Move Power Boulders (Partner) — Lite | E12: Same idea, lower intensity holds/angles, more coaching touch-points. | F12: Per pair, rotate roles | G12: Bouldering wall | H12: Adapted from Intermediate version | I12: =COUNTIF('Log a Workout'!$C$5:$C$200,D12) | J12: FALSE
A13: =IF(D13="","",ROW()-5) | B13: Strength | C13: Advanced | D13: One-Arm / Weighted Hangs | E13: Progressive hang protocol. | F13: 6x3-5 sec | G13: Hangboard, weight belt | H13: From 9/1 plan | I13: =COUNTIF('Log a Workout'!$C$5:$C$200,D13) | J13: FALSE
A14: =IF(D14="","",ROW()-5) | B14: Strength | C14: Advanced | D14: Weighted Pull-Ups | F14: 4x4 reps | G14: Pull-up bar, weight belt | H14: From 9/1 plan | I14: =COUNTIF('Log a Workout'!$C$5:$C$200,D14) | J14: FALSE
A15: =IF(D15="","",ROW()-5) | B15: Strength | C15: Intermediate | D15: Cable Bench / Incline Press | F15: 3x6 | G15: Cable machine | H15: From 9/1 plan | I15: =COUNTIF('Log a Workout'!$C$5:$C$200,D15) | J15: FALSE
A16: =IF(D16="","",ROW()-5) | B16: Strength | C16: Intermediate | D16: Box Jumps | F16: 3x3 | G16: Plyo box | H16: From 9/1 plan | I16: =COUNTIF('Log a Workout'!$C$5:$C$200,D16) | J16: FALSE
A17: =IF(D17="","",ROW()-5) | B17: Technique/Skill | C17: Advanced | D17: Lock-Off Hover Drill (Overhang) | E17: Overhangs only, hold each position, stable body, not locked off. 10 boulders, 3 min rest between. | F17: 10 boulders, 3 min rest | G17: Overhung terrain | H17: From 9/3 plan | I17: =COUNTIF('Log a Workout'!$C$5:$C$200,D17) | J17: FALSE
A18: =IF(D18="","",ROW()-5) | B18: Technique/Skill | C18: Advanced | D18: Foot Cut Drill | E18: Boulders ~1 grade below flash. Jump between moves, establish foot control on first swing in. Focus on accuracy and shoulder tension/control. Steep terrain only. | F18: 6 boulders x2 sets, 3 min rest, 5 min between sets | G18: Steep bouldering terrain | H18: From 9/22 plan | I18: =COUNTIF('Log a Workout'!$C$5:$C$200,D18) | J18: FALSE
A19: =IF(D19="","",ROW()-5) | B19: Technique/Skill | C19: Intermediate | D19: Balance Work — Back Flags/Steps | E19: Back flags only, back steps only, open-hip squats only; off foot engaged every rep. | F19: 5 boulders per constraint | G19: Bouldering wall | H19: From 9/8 plan | I19: =COUNTIF('Log a Workout'!$C$5:$C$200,D19) | J19: FALSE
A20: =IF(D20="","",ROW()-5) | B20: Technique/Skill | C20: Developing | D20: Open-Feet Technique Circuit | E20: Heel hooks only, drop knees only, back-steps only (with smear off foot) — 3 boulders each. | F20: 3 boulders per constraint | G20: Bouldering wall | H20: From 9/8 plan (younger group) | I20: =COUNTIF('Log a Workout'!$C$5:$C$200,D20) | J20: FALSE
A21: =IF(D21="","",ROW()-5) | B21: Coordination/Balance | C21: Developing | D21: Coordination/Power/Balance Skills L1-4 | E21: One at a time, 1 min max, 2 attempts max per skill. | F21: 1 min max, 2 attempts | G21: Spray wall / moon board | H21: From 9/3 plan | I21: =COUNTIF('Log a Workout'!$C$5:$C$200,D21) | J21: FALSE
A22: =IF(D22="","",ROW()-5) | B22: Coordination/Balance | C22: Developing | D22: Sloth Climbing Drill | E22: Move upward slowly with both hands and feet; focus on control and foot placement accuracy. | F22: Full wall, slow pace | G22: Any wall | H22: From 9/22 plan (younger group) | I22: =COUNTIF('Log a Workout'!$C$5:$C$200,D22) | J22: FALSE
A23: =IF(D23="","",ROW()-5) | B23: Coordination/Balance | C23: All Levels | D23: Boulder Golf | E23: Golf-style scoring across boulders in groups; 1 v-up per point after each boulder. | F23: Per group rotation | G23: Bouldering wall | H23: From 9/10 plan — good for confidence/fun | I23: =COUNTIF('Log a Workout'!$C$5:$C$200,D23) | J23: FALSE
A24: =IF(D24="","",ROW()-5) | B24: Core | C24: All Levels | D24: Hanging Core Circuit | E24: 4 sets, 4 exercises. | F24: 4x4 exercises | G24: Pull-up bar / hangboard | H24: Standard closer | I24: =COUNTIF('Log a Workout'!$C$5:$C$200,D24) | J24: FALSE
A25: =IF(D25="","",ROW()-5) | B25: Core | C25: All Levels | D25: Floor Core + Stretch | E25: 10 min floor core circuit followed by team stretch. | F25: 10 min | G25: Mats | H25: Standard closer | I25: =COUNTIF('Log a Workout'!$C$5:$C$200,D25) | J25: FALSE
A26: =IF(D26="","",ROW()-5) | B26: Stretch/Cooldown | C26: All Levels | D26: Team Stretch | E26: Full-body static stretch, cool down. | F26: 10-15 min | G26: Mats | H26: Standard closer | I26: =COUNTIF('Log a Workout'!$C$5:$C$200,D26) | J26: FALSE
A27: =IF(D27="","",ROW()-5) | I27: =IF(D27="","",COUNTIF('Log a Workout'!$C$5:$C$200,D27)) | J27: FALSE
A28: =IF(D28="","",ROW()-5) | I28: =IF(D28="","",COUNTIF('Log a Workout'!$C$5:$C$200,D28)) | J28: FALSE
A29: =IF(D29="","",ROW()-5) | I29: =IF(D29="","",COUNTIF('Log a Workout'!$C$5:$C$200,D29)) | J29: FALSE
A30: =IF(D30="","",ROW()-5) | I30: =IF(D30="","",COUNTIF('Log a Workout'!$C$5:$C$200,D30)) | J30: FALSE
A31: =IF(D31="","",ROW()-5) | I31: =IF(D31="","",COUNTIF('Log a Workout'!$C$5:$C$200,D31)) | J31: FALSE
A32: =IF(D32="","",ROW()-5) | I32: =IF(D32="","",COUNTIF('Log a Workout'!$C$5:$C$200,D32)) | J32: FALSE
A33: =IF(D33="","",ROW()-5) | I33: =IF(D33="","",COUNTIF('Log a Workout'!$C$5:$C$200,D33)) | J33: FALSE
A34: =IF(D34="","",ROW()-5) | I34: =IF(D34="","",COUNTIF('Log a Workout'!$C$5:$C$200,D34)) | J34: FALSE
A35: =IF(D35="","",ROW()-5) | I35: =IF(D35="","",COUNTIF('Log a Workout'!$C$5:$C$200,D35)) | J35: FALSE
A36: =IF(D36="","",ROW()-5) | I36: =IF(D36="","",COUNTIF('Log a Workout'!$C$5:$C$200,D36)) | J36: FALSE
A37: =IF(D37="","",ROW()-5) | I37: =IF(D37="","",COUNTIF('Log a Workout'!$C$5:$C$200,D37)) | J37: FALSE
A38: =IF(D38="","",ROW()-5) | I38: =IF(D38="","",COUNTIF('Log a Workout'!$C$5:$C$200,D38)) | J38: FALSE
... A120: =IF(D120="","",ROW()-5) | I120: =IF(D120="","",COUNTIF('Log a Workout'!$C$5:$C$200,D120)) | J120: FALSE

Sheet Rotation Schedule
A1: Rotation Schedule
A2: Thursday only — auto-generated from Settings (start date, group names) and the Coach Profiles tab (who's flagged for Thursday). Running low on weeks? Tap the checkbox below — works on a phone too.
A3: Add 4 weeks: | B3: FALSE | C3: tap TRUE — extends this and Full Team Calendar by 4 weeks; tap again for 4 more
A4: Week # | B4: Date | C4: Cycle Wk (1-4) | D4: Featured Tier | E4: Lead Planning Coach | F4: Other Groups This Week (fill in) | G4: Notes
A5: 1 | B5: =SeasonStart | C5: =MOD(A5-1,4)+1 | D5: =IF(C5=4,"All Team",INDEX(GroupNamesRange,C5)) | E5: =IF(C5=4,"All Coaches",IF(SUMPRODUCT(--(ThursdayCoachList<>""))=0,"— add a Thursday coach —",INDEX(ThursdayCoachList,MOD(A5-1,SUMPRODUCT(--(ThursdayCoachList<>"")))+1)))
A6: =A5+1 | B6: =B5+7 | C6: =MOD(A6-1,4)+1 | D6: =IF(C6=4,"All Team",INDEX(GroupNamesRange,C6)) | E6: =IF(C6=4,"All Coaches",IF(SUMPRODUCT(--(ThursdayCoachList<>""))=0,"— add a Thursday coach —",INDEX(ThursdayCoachList,MOD(A6-1,SUMPRODUCT(--(ThursdayCoachList<>"")))+1)))
A7: =A6+1 | B7: =B6+7 | C7: =MOD(A7-1,4)+1 | D7: =IF(C7=4,"All Team",INDEX(GroupNamesRange,C7)) | E7: =IF(C7=4,"All Coaches",IF(SUMPRODUCT(--(ThursdayCoachList<>""))=0,"— add a Thursday coach —",INDEX(ThursdayCoachList,MOD(A7-1,SUMPRODUCT(--(ThursdayCoachList<>"")))+1)))
A8: =A7+1 | B8: =B7+7 | C8: =MOD(A8-1,4)+1 | D8: =IF(C8=4,"All Team",INDEX(GroupNamesRange,C8)) | E8: =IF(C8=4,"All Coaches",IF(SUMPRODUCT(--(ThursdayCoachList<>""))=0,"— add a Thursday coach —",INDEX(ThursdayCoachList,MOD(A8-1,SUMPRODUCT(--(ThursdayCoachList<>"")))+1)))
A9: =A8+1 | B9: =B8+7 | C9: =MOD(A9-1,4)+1 | D9: =IF(C9=4,"All Team",INDEX(GroupNamesRange,C9)) | E9: =IF(C9=4,"All Coaches",IF(SUMPRODUCT(--(ThursdayCoachList<>""))=0,"— add a Thursday coach —",INDEX(ThursdayCoachList,MOD(A9-1,SUMPRODUCT(--(ThursdayCoachList<>"")))+1)))
A10: =A9+1 | B10: =B9+7 | C10: =MOD(A10-1,4)+1 | D10: =IF(C10=4,"All Team",INDEX(GroupNamesRange,C10)) | E10: =IF(C10=4,"All Coaches",IF(SUMPRODUCT(--(ThursdayCoachList<>""))=0,"— add a Thursday coach —",INDEX(ThursdayCoachList,MOD(A10-1,SUMPRODUCT(--(ThursdayCoachList<>"")))+1)))
A11: =A10+1 | B11: =B10+7 | C11: =MOD(A11-1,4)+1 | D11: =IF(C11=4,"All Team",INDEX(GroupNamesRange,C11)) | E11: =IF(C11=4,"All Coaches",IF(SUMPRODUCT(--(ThursdayCoachList<>""))=0,"— add a Thursday coach —",INDEX(ThursdayCoachList,MOD(A11-1,SUMPRODUCT(--(ThursdayCoachList<>"")))+1)))
A12: =A11+1 | B12: =B11+7 | C12: =MOD(A12-1,4)+1 | D12: =IF(C12=4,"All Team",INDEX(GroupNamesRange,C12)) | E12: =IF(C12=4,"All Coaches",IF(SUMPRODUCT(--(ThursdayCoachList<>""))=0,"— add a Thursday coach —",INDEX(ThursdayCoachList,MOD(A12-1,SUMPRODUCT(--(ThursdayCoachList<>"")))+1)))
A13: =A12+1 | B13: =B12+7 | C13: =MOD(A13-1,4)+1 | D13: =IF(C13=4,"All Team",INDEX(GroupNamesRange,C13)) | E13: =IF(C13=4,"All Coaches",IF(SUMPRODUCT(--(ThursdayCoachList<>""))=0,"— add a Thursday coach —",INDEX(ThursdayCoachList,MOD(A13-1,SUMPRODUCT(--(ThursdayCoachList<>"")))+1)))
A14: =A13+1 | B14: =B13+7 | C14: =MOD(A14-1,4)+1 | D14: =IF(C14=4,"All Team",INDEX(GroupNamesRange,C14)) | E14: =IF(C14=4,"All Coaches",IF(SUMPRODUCT(--(ThursdayCoachList<>""))=0,"— add a Thursday coach —",INDEX(ThursdayCoachList,MOD(A14-1,SUMPRODUCT(--(ThursdayCoachList<>"")))+1)))
A15: =A14+1 | B15: =B14+7 | C15: =MOD(A15-1,4)+1 | D15: =IF(C15=4,"All Team",INDEX(GroupNamesRange,C15)) | E15: =IF(C15=4,"All Coaches",IF(SUMPRODUCT(--(ThursdayCoachList<>""))=0,"— add a Thursday coach —",INDEX(ThursdayCoachList,MOD(A15-1,SUMPRODUCT(--(ThursdayCoachList<>"")))+1)))
A16: =A15+1 | B16: =B15+7 | C16: =MOD(A16-1,4)+1 | D16: =IF(C16=4,"All Team",INDEX(GroupNamesRange,C16)) | E16: =IF(C16=4,"All Coaches",IF(SUMPRODUCT(--(ThursdayCoachList<>""))=0,"— add a Thursday coach —",INDEX(ThursdayCoachList,MOD(A16-1,SUMPRODUCT(--(ThursdayCoachList<>"")))+1)))
A17: =A16+1 | B17: =B16+7 | C17: =MOD(A17-1,4)+1 | D17: =IF(C17=4,"All Team",INDEX(GroupNamesRange,C17)) | E17: =IF(C17=4,"All Coaches",IF(SUMPRODUCT(--(ThursdayCoachList<>""))=0,"— add a Thursday coach —",INDEX(ThursdayCoachList,MOD(A17-1,SUMPRODUCT(--(ThursdayCoachList<>"")))+1)))
... A20: =A19+1 | B20: =B19+7 | C20: =MOD(A20-1,4)+1 | D20: =IF(C20=4,"All Team",INDEX(GroupNamesRange,C20)) | E20: =IF(C20=4,"All Coaches",IF(SUMPRODUCT(--(ThursdayCoachList<>""))=0,"— add a Thursday coach —",INDEX(ThursdayCoachList,MOD(A20-1,SUMPRODUCT(--(ThursdayCoachList<>"")))+1)))

Sheet Full Team Calendar
A1: Full Team Calendar
A2: Every practice day (Mon/Tue/Thu) for the whole season in one place — the piece meant to eventually cover the entire team, not just Thursday. Coach columns pull from the Coach Profiles tab; Thursday's tier pulls from Rotation Schedule. Notes/Format is open for whatever the Monday/Tuesday coaches already run.
A4: Date | B4: Day | C4: Coach(es) on Duty | D4: Thursday Featured Tier | E4: Notes / Format (fill in)
A5: =SeasonStart-3 | B5: =TEXT(A5,"dddd") | C5: =IF(SUMPRODUCT(--(MondayCoachList<>""))=0,"— add a Monday coach —",INDEX(MondayCoachList,MOD(0,SUMPRODUCT(--(MondayCoachList<>"")))+1)) | D5: —
A6: =A5+1 | B6: =TEXT(A6,"dddd") | C6: =IF(SUMPRODUCT(--(TuesdayCoachList<>""))=0,"— add a Tuesday coach —",INDEX(TuesdayCoachList,MOD(0,SUMPRODUCT(--(TuesdayCoachList<>"")))+1)) | D6: —
A7: =A6+2 | B7: =TEXT(A7,"dddd") | C7: =IFERROR(INDEX('Rotation Schedule'!$E$5:$E$20,MATCH(A7,'Rotation Schedule'!$B$5:$B$20,0)),"") | D7: =IFERROR(INDEX('Rotation Schedule'!$D$5:$D$20,MATCH(A7,'Rotation Schedule'!$B$5:$B$20,0)),"")
A8: =A5+7 | B8: =TEXT(A8,"dddd") | C8: =IF(SUMPRODUCT(--(MondayCoachList<>""))=0,"— add a Monday coach —",INDEX(MondayCoachList,MOD(1,SUMPRODUCT(--(MondayCoachList<>"")))+1)) | D8: —
A9: =A8+1 | B9: =TEXT(A9,"dddd") | C9: =IF(SUMPRODUCT(--(TuesdayCoachList<>""))=0,"— add a Tuesday coach —",INDEX(TuesdayCoachList,MOD(1,SUMPRODUCT(--(TuesdayCoachList<>"")))+1)) | D9: —
A10: =A9+2 | B10: =TEXT(A10,"dddd") | C10: =IFERROR(INDEX('Rotation Schedule'!$E$5:$E$20,MATCH(A10,'Rotation Schedule'!$B$5:$B$20,0)),"") | D10: =IFERROR(INDEX('Rotation Schedule'!$D$5:$D$20,MATCH(A10,'Rotation Schedule'!$B$5:$B$20,0)),"")
A11: =A8+7 | B11: =TEXT(A11,"dddd") | C11: =IF(SUMPRODUCT(--(MondayCoachList<>""))=0,"— add a Monday coach —",INDEX(MondayCoachList,MOD(2,SUMPRODUCT(--(MondayCoachList<>"")))+1)) | D11: —
A12: =A11+1 | B12: =TEXT(A12,"dddd") | C12: =IF(SUMPRODUCT(--(TuesdayCoachList<>""))=0,"— add a Tuesday coach —",INDEX(TuesdayCoachList,MOD(2,SUMPRODUCT(--(TuesdayCoachList<>"")))+1)) | D12: —
A13: =A12+2 | B13: =TEXT(A13,"dddd") | C13: =IFERROR(INDEX('Rotation Schedule'!$E$5:$E$20,MATCH(A13,'Rotation Schedule'!$B$5:$B$20,0)),"") | D13: =IFERROR(INDEX('Rotation Schedule'!$D$5:$D$20,MATCH(A13,'Rotation Schedule'!$B$5:$B$20,0)),"")
A14: =A11+7 | B14: =TEXT(A14,"dddd") | C14: =IF(SUMPRODUCT(--(MondayCoachList<>""))=0,"— add a Monday coach —",INDEX(MondayCoachList,MOD(3,SUMPRODUCT(--(MondayCoachList<>"")))+1)) | D14: —
A15: =A14+1 | B15: =TEXT(A15,"dddd") | C15: =IF(SUMPRODUCT(--(TuesdayCoachList<>""))=0,"— add a Tuesday coach —",INDEX(TuesdayCoachList,MOD(3,SUMPRODUCT(--(TuesdayCoachList<>"")))+1)) | D15: —
A16: =A15+2 | B16: =TEXT(A16,"dddd") | C16: =IFERROR(INDEX('Rotation Schedule'!$E$5:$E$20,MATCH(A16,'Rotation Schedule'!$B$5:$B$20,0)),"") | D16: =IFERROR(INDEX('Rotation Schedule'!$D$5:$D$20,MATCH(A16,'Rotation Schedule'!$B$5:$B$20,0)),"")
A17: =A14+7 | B17: =TEXT(A17,"dddd") | C17: =IF(SUMPRODUCT(--(MondayCoachList<>""))=0,"— add a Monday coach —",INDEX(MondayCoachList,MOD(4,SUMPRODUCT(--(MondayCoachList<>"")))+1)) | D17: —
A18: =A17+1 | B18: =TEXT(A18,"dddd") | C18: =IF(SUMPRODUCT(--(TuesdayCoachList<>""))=0,"— add a Tuesday coach —",INDEX(TuesdayCoachList,MOD(4,SUMPRODUCT(--(TuesdayCoachList<>"")))+1)) | D18: —
A19: =A18+2 | B19: =TEXT(A19,"dddd") | C19: =IFERROR(INDEX('Rotation Schedule'!$E$5:$E$20,MATCH(A19,'Rotation Schedule'!$B$5:$B$20,0)),"") | D19: =IFERROR(INDEX('Rotation Schedule'!$D$5:$D$20,MATCH(A19,'Rotation Schedule'!$B$5:$B$20,0)),"")
A20: =A17+7 | B20: =TEXT(A20,"dddd") | C20: =IF(SUMPRODUCT(--(MondayCoachList<>""))=0,"— add a Monday coach —",INDEX(MondayCoachList,MOD(5,SUMPRODUCT(--(MondayCoachList<>"")))+1)) | D20: —
A21: =A20+1 | B21: =TEXT(A21,"dddd") | C21: =IF(SUMPRODUCT(--(TuesdayCoachList<>""))=0,"— add a Tuesday coach —",INDEX(TuesdayCoachList,MOD(5,SUMPRODUCT(--(TuesdayCoachList<>"")))+1)) | D21: —
A22: =A21+2 | B22: =TEXT(A22,"dddd") | C22: =IFERROR(INDEX('Rotation Schedule'!$E$5:$E$20,MATCH(A22,'Rotation Schedule'!$B$5:$B$20,0)),"") | D22: =IFERROR(INDEX('Rotation Schedule'!$D$5:$D$20,MATCH(A22,'Rotation Schedule'!$B$5:$B$20,0)),"")
A23: =A20+7 | B23: =TEXT(A23,"dddd") | C23: =IF(SUMPRODUCT(--(MondayCoachList<>""))=0,"— add a Monday coach —",INDEX(MondayCoachList,MOD(6,SUMPRODUCT(--(MondayCoachList<>"")))+1)) | D23: —
A24: =A23+1 | B24: =TEXT(A24,"dddd") | C24: =IF(SUMPRODUCT(--(TuesdayCoachList<>""))=0,"— add a Tuesday coach —",INDEX(TuesdayCoachList,MOD(6,SUMPRODUCT(--(TuesdayCoachList<>"")))+1)) | D24: —
A25: =A24+2 | B25: =TEXT(A25,"dddd") | C25: =IFERROR(INDEX('Rotation Schedule'!$E$5:$E$20,MATCH(A25,'Rotation Schedule'!$B$5:$B$20,0)),"") | D25: =IFERROR(INDEX('Rotation Schedule'!$D$5:$D$20,MATCH(A25,'Rotation Schedule'!$B$5:$B$20,0)),"")
A26: =A23+7 | B26: =TEXT(A26,"dddd") | C26: =IF(SUMPRODUCT(--(MondayCoachList<>""))=0,"— add a Monday coach —",INDEX(MondayCoachList,MOD(7,SUMPRODUCT(--(MondayCoachList<>"")))+1)) | D26: —
A27: =A26+1 | B27: =TEXT(A27,"dddd") | C27: =IF(SUMPRODUCT(--(TuesdayCoachList<>""))=0,"— add a Tuesday coach —",INDEX(TuesdayCoachList,MOD(7,SUMPRODUCT(--(TuesdayCoachList<>"")))+1)) | D27: —
A28: =A27+2 | B28: =TEXT(A28,"dddd") | C28: =IFERROR(INDEX('Rotation Schedule'!$E$5:$E$20,MATCH(A28,'Rotation Schedule'!$B$5:$B$20,0)),"") | D28: =IFERROR(INDEX('Rotation Schedule'!$D$5:$D$20,MATCH(A28,'Rotation Schedule'!$B$5:$B$20,0)),"")
A29: =A26+7 | B29: =TEXT(A29,"dddd") | C29: =IF(SUMPRODUCT(--(MondayCoachList<>""))=0,"— add a Monday coach —",INDEX(MondayCoachList,MOD(8,SUMPRODUCT(--(MondayCoachList<>"")))+1)) | D29: —
A30: =A29+1 | B30: =TEXT(A30,"dddd") | C30: =IF(SUMPRODUCT(--(TuesdayCoachList<>""))=0,"— add a Tuesday coach —",INDEX(TuesdayCoachList,MOD(8,SUMPRODUCT(--(TuesdayCoachList<>"")))+1)) | D30: —
A31: =A30+2 | B31: =TEXT(A31,"dddd") | C31: =IFERROR(INDEX('Rotation Schedule'!$E$5:$E$20,MATCH(A31,'Rotation Schedule'!$B$5:$B$20,0)),"") | D31: =IFERROR(INDEX('Rotation Schedule'!$D$5:$D$20,MATCH(A31,'Rotation Schedule'!$B$5:$B$20,0)),"")
A32: =A29+7 | B32: =TEXT(A32,"dddd") | C32: =IF(SUMPRODUCT(--(MondayCoachList<>""))=0,"— add a Monday coach —",INDEX(MondayCoachList,MOD(9,SUMPRODUCT(--(MondayCoachList<>"")))+1)) | D32: —
A33: =A32+1 | B33: =TEXT(A33,"dddd") | C33: =IF(SUMPRODUCT(--(TuesdayCoachList<>""))=0,"— add a Tuesday coach —",INDEX(TuesdayCoachList,MOD(9,SUMPRODUCT(--(TuesdayCoachList<>"")))+1)) | D33: —
A34: =A33+2 | B34: =TEXT(A34,"dddd") | C34: =IFERROR(INDEX('Rotation Schedule'!$E$5:$E$20,MATCH(A34,'Rotation Schedule'!$B$5:$B$20,0)),"") | D34: =IFERROR(INDEX('Rotation Schedule'!$D$5:$D$20,MATCH(A34,'Rotation Schedule'!$B$5:$B$20,0)),"")
A35: =A32+7 | B35: =TEXT(A35,"dddd") | C35: =IF(SUMPRODUCT(--(MondayCoachList<>""))=0,"— add a Monday coach —",INDEX(MondayCoachList,MOD(10,SUMPRODUCT(--(MondayCoachList<>"")))+1)) | D35: —
A36: =A35+1 | B36: =TEXT(A36,"dddd") | C36: =IF(SUMPRODUCT(--(TuesdayCoachList<>""))=0,"— add a Tuesday coach —",INDEX(TuesdayCoachList,MOD(10,SUMPRODUCT(--(TuesdayCoachList<>"")))+1)) | D36: —
A37: =A36+2 | B37: =TEXT(A37,"dddd") | C37: =IFERROR(INDEX('Rotation Schedule'!$E$5:$E$20,MATCH(A37,'Rotation Schedule'!$B$5:$B$20,0)),"") | D37: =IFERROR(INDEX('Rotation Schedule'!$D$5:$D$20,MATCH(A37,'Rotation Schedule'!$B$5:$B$20,0)),"")
A38: =A35+7 | B38: =TEXT(A38,"dddd") | C38: =IF(SUMPRODUCT(--(MondayCoachList<>""))=0,"— add a Monday coach —",INDEX(MondayCoachList,MOD(11,SUMPRODUCT(--(MondayCoachList<>"")))+1)) | D38: —
A39: =A38+1 | B39: =TEXT(A39,"dddd") | C39: =IF(SUMPRODUCT(--(TuesdayCoachList<>""))=0,"— add a Tuesday coach —",INDEX(TuesdayCoachList,MOD(11,SUMPRODUCT(--(TuesdayCoachList<>"")))+1)) | D39: —
A40: =A39+2 | B40: =TEXT(A40,"dddd") | C40: =IFERROR(INDEX('Rotation Schedule'!$E$5:$E$20,MATCH(A40,'Rotation Schedule'!$B$5:$B$20,0)),"") | D40: =IFERROR(INDEX('Rotation Schedule'!$D$5:$D$20,MATCH(A40,'Rotation Schedule'!$B$5:$B$20,0)),"")
A41: =A38+7 | B41: =TEXT(A41,"dddd") | C41: =IF(SUMPRODUCT(--(MondayCoachList<>""))=0,"— add a Monday coach —",INDEX(MondayCoachList,MOD(12,SUMPRODUCT(--(MondayCoachList<>"")))+1)) | D41: —
...

Sheet Progress Log
A1: Progress Log
A2: One row per data point. Type straight into a blank row to add one — works on a phone. Tap the checkbox below to jump to the next open row. Filter by Athlete (Data > Create a filter) to see one climber's history over the season.
A3: New row: | B3: FALSE | C3: tap TRUE to jump to the next open row
A4: Date | B4: Athlete | C4: Metric Type | D4: Value | E4: Notes / Context | F4: Logged By
A5: 46273 | B5: Alex Rivera | C5: Flash Grade | D5: V6 | E5: Consistently flashing V6 on steep terrain now. | F5: Coach 1 Name
A6: 46280 | B6: Alex Rivera | C6: Comp Placement | D6: 2nd place | E6: Regional qualifier, strong finals performance. | F6: Coach 2 Name
A7: 46273 | B7: Sam Nguyen | C7: Coach Note | D7: — | E7: Big improvement in foot placement accuracy this week. | F7: Your Name

Sheet Settings
A1: Settings — the control panel
A2: Edit only the yellow cells. Everything else in the workbook reads from here.
A4: GROUP NAMES
A5: Group A — top performers | B5: Advanced
A6: Group B — mid-range | B6: Intermediate
A7: Group C — developing | B7: Developing
A9: COACHES
A10: Coaches now have their own tab -> see "Coach Profiles". Add, remove, or reassign coaches there (including which day(s) they coach) and every dropdown and rotation elsewhere in this workbook updates automatically — no fixed coach count here anymore.
A14: THURSDAY PRACTICE TIMING
A15: These describe the tiered Thursday block specifically. Monday/Tuesday keep whatever format the head coach already runs — see the Full Team Calendar tab.
A16: Season start date (first Thursday under this system) | B16: 46289
A17: Number of weeks scheduled below | B17: 16
A18: Practice start time | B18: 5:30 PM
A19: Practice end time | B19: 8:00 PM
A20: Team warm-up (minutes) | B20: 45
A21: Tiered group block (minutes) | B21: 90
A22: Team stretch / cooldown (minutes) | B22: 15
A23: Check: block lengths sum to practice length? | B23: =IF((B20+B21+B22)=((HOUR(TIMEVALUE(B19))*60+MINUTE(TIMEVALUE(B19)))-(HOUR(TIMEVALUE(B18))*60+MINUTE(TIMEVALUE(B18)))),"OK","check times")
A25: 4-WEEK ROTATION PATTERN (auto — reads Group Names above)
A26: Cycle Week | B26: Featured Tier
A27: 1 | B27: =B5
A28: 2 | B28: =B6
A29: 3 | B29: =B7
A30: 4 | B30: All Team
A32: DROPDOWN LIST HELPERS (used by data-validation dropdowns — don't delete)
A33: Group + All Team | C33: Group + All Levels
A34: =B5 | C34: =B5
A35: =B6 | C35: =B6
A36: =B7 | C36: =B7
A37: All Team | C37: All Levels
A39: Block Types (Log a Workout, Exercise Library)
A40: Warm-up
A41: Strength
A42: Power
A43: Technique/Skill
A44: Coordination/Balance
A45: Core
A46: Stretch/Cooldown
A47: Other
